[2023-11-01T15:34:40.419+0700] {taskinstance.py:1157} INFO - Dependencies all met for dep_context=non-requeueable deps ti=<TaskInstance: api_crawler.crawl_data scheduled__2023-11-01T08:20:00+00:00 [queued]>
[2023-11-01T15:34:40.430+0700] {taskinstance.py:1157} INFO - Dependencies all met for dep_context=requeueable deps ti=<TaskInstance: api_crawler.crawl_data scheduled__2023-11-01T08:20:00+00:00 [queued]>
[2023-11-01T15:34:40.431+0700] {taskinstance.py:1359} INFO - Starting attempt 1 of 2
[2023-11-01T15:34:40.459+0700] {taskinstance.py:1380} INFO - Executing <Task(PythonOperator): crawl_data> on 2023-11-01 08:20:00+00:00
[2023-11-01T15:34:40.479+0700] {standard_task_runner.py:57} INFO - Started process 123 to run task
[2023-11-01T15:34:40.504+0700] {standard_task_runner.py:84} INFO - Running: ['***', 'tasks', 'run', 'api_crawler', 'crawl_data', 'scheduled__2023-11-01T08:20:00+00:00', '--job-id', '72', '--raw', '--subdir', 'DAGS_FOLDER/crawl_api_dag.py', '--cfg-path', '/tmp/tmpxxq6san0']
[2023-11-01T15:34:40.511+0700] {standard_task_runner.py:85} INFO - Job 72: Subtask crawl_data
[2023-11-01T15:34:40.578+0700] {task_command.py:415} INFO - Running <TaskInstance: api_crawler.crawl_data scheduled__2023-11-01T08:20:00+00:00 [running]> on host e8879d3484bb
[2023-11-01T15:34:40.763+0700] {taskinstance.py:1660} INFO - Exporting env vars: AIRFLOW_CTX_DAG_EMAIL='***@example.com' AIRFLOW_CTX_DAG_OWNER='***' AIRFLOW_CTX_DAG_ID='api_crawler' AIRFLOW_CTX_TASK_ID='crawl_data' AIRFLOW_CTX_EXECUTION_DATE='2023-11-01T08:20:00+00:00' AIRFLOW_CTX_TRY_NUMBER='1' AIRFLOW_CTX_DAG_RUN_ID='scheduled__2023-11-01T08:20:00+00:00'
[2023-11-01T15:34:53.304+0700] {taskinstance.py:1935} ERROR - Task failed with exception
Traceback (most recent call last):
  File "/home/airflow/.local/lib/python3.9/site-packages/airflow/operators/python.py", line 192, in execute
    return_value = self.execute_callable()
  File "/home/airflow/.local/lib/python3.9/site-packages/airflow/operators/python.py", line 209, in execute_callable
    return self.python_callable(*self.op_args, **self.op_kwargs)
  File "/opt/airflow/dags/api_to_delta.py", line 3, in run
    processor = DataProcessor()
  File "/opt/airflow/dags/spark/processor.py", line 27, in __init__
    self.spark = configure_spark_with_delta_pip(self.spark).getOrCreate()
  File "/home/airflow/.local/lib/python3.9/site-packages/pyspark/sql/session.py", line 269, in getOrCreate
    sc = SparkContext.getOrCreate(sparkConf)
  File "/home/airflow/.local/lib/python3.9/site-packages/pyspark/context.py", line 483, in getOrCreate
    SparkContext(conf=conf or SparkConf())
  File "/home/airflow/.local/lib/python3.9/site-packages/pyspark/context.py", line 195, in __init__
    SparkContext._ensure_initialized(self, gateway=gateway, conf=conf)
  File "/home/airflow/.local/lib/python3.9/site-packages/pyspark/context.py", line 417, in _ensure_initialized
    SparkContext._gateway = gateway or launch_gateway(conf)
  File "/home/airflow/.local/lib/python3.9/site-packages/pyspark/java_gateway.py", line 106, in launch_gateway
    raise RuntimeError("Java gateway process exited before sending its port number")
RuntimeError: Java gateway process exited before sending its port number
[2023-11-01T15:34:53.412+0700] {taskinstance.py:1398} INFO - Marking task as UP_FOR_RETRY. dag_id=api_crawler, task_id=crawl_data, execution_date=20231101T082000, start_date=20231101T083440, end_date=20231101T083453
[2023-11-01T15:34:53.487+0700] {standard_task_runner.py:104} ERROR - Failed to execute job 72 for task crawl_data (Java gateway process exited before sending its port number; 123)
[2023-11-01T15:34:53.537+0700] {local_task_job_runner.py:228} INFO - Task exited with return code 1
[2023-11-01T15:34:53.610+0700] {taskinstance.py:2776} INFO - 0 downstream tasks scheduled from follow-on schedule check
