[2023-11-01T12:36:23.895+0700] {taskinstance.py:1157} INFO - Dependencies all met for dep_context=non-requeueable deps ti=<TaskInstance: etl_pipeline.wait_for_first_dag scheduled__2023-11-01T05:20:00+00:00 [queued]>
[2023-11-01T12:36:23.900+0700] {taskinstance.py:1157} INFO - Dependencies all met for dep_context=requeueable deps ti=<TaskInstance: etl_pipeline.wait_for_first_dag scheduled__2023-11-01T05:20:00+00:00 [queued]>
[2023-11-01T12:36:23.901+0700] {taskinstance.py:1359} INFO - Starting attempt 2 of 2
[2023-11-01T12:36:23.908+0700] {taskinstance.py:1380} INFO - Executing <Task(ExternalTaskSensor): wait_for_first_dag> on 2023-11-01 05:20:00+00:00
[2023-11-01T12:36:23.913+0700] {standard_task_runner.py:57} INFO - Started process 148 to run task
[2023-11-01T12:36:23.917+0700] {standard_task_runner.py:84} INFO - Running: ['***', 'tasks', 'run', 'etl_pipeline', 'wait_for_first_dag', 'scheduled__2023-11-01T05:20:00+00:00', '--job-id', '8', '--raw', '--subdir', 'DAGS_FOLDER/etl_dag.py', '--cfg-path', '/tmp/tmpxexgv0in']
[2023-11-01T12:36:23.920+0700] {standard_task_runner.py:85} INFO - Job 8: Subtask wait_for_first_dag
[2023-11-01T12:36:23.958+0700] {task_command.py:415} INFO - Running <TaskInstance: etl_pipeline.wait_for_first_dag scheduled__2023-11-01T05:20:00+00:00 [running]> on host 30336f6a0571
[2023-11-01T12:36:24.022+0700] {taskinstance.py:1660} INFO - Exporting env vars: AIRFLOW_CTX_DAG_EMAIL='***@example.com' AIRFLOW_CTX_DAG_OWNER='***' AIRFLOW_CTX_DAG_ID='etl_pipeline' AIRFLOW_CTX_TASK_ID='wait_for_first_dag' AIRFLOW_CTX_EXECUTION_DATE='2023-11-01T05:20:00+00:00' AIRFLOW_CTX_TRY_NUMBER='2' AIRFLOW_CTX_DAG_RUN_ID='scheduled__2023-11-01T05:20:00+00:00'
[2023-11-01T12:36:24.037+0700] {taskinstance.py:1935} ERROR - Task failed with exception
Traceback (most recent call last):
  File "/home/airflow/.local/lib/python3.9/site-packages/airflow/sensors/external_task.py", line 334, in execute
    super().execute(context)
  File "/home/airflow/.local/lib/python3.9/site-packages/airflow/sensors/base.py", line 257, in execute
    raise e
  File "/home/airflow/.local/lib/python3.9/site-packages/airflow/sensors/base.py", line 239, in execute
    poke_return = self.poke(context)
  File "/home/airflow/.local/lib/python3.9/site-packages/airflow/utils/session.py", line 77, in wrapper
    return func(*args, session=session, **kwargs)
  File "/home/airflow/.local/lib/python3.9/site-packages/airflow/sensors/external_task.py", line 241, in poke
    serialized_dttm_filter = ",".join(dt.isoformat() for dt in dttm_filter)
  File "/home/airflow/.local/lib/python3.9/site-packages/airflow/sensors/external_task.py", line 241, in <genexpr>
    serialized_dttm_filter = ",".join(dt.isoformat() for dt in dttm_filter)
AttributeError: 'NoneType' object has no attribute 'isoformat'
[2023-11-01T12:36:24.044+0700] {taskinstance.py:1398} INFO - Marking task as FAILED. dag_id=etl_pipeline, task_id=wait_for_first_dag, execution_date=20231101T052000, start_date=20231101T053623, end_date=20231101T053624
[2023-11-01T12:36:24.053+0700] {standard_task_runner.py:104} ERROR - Failed to execute job 8 for task wait_for_first_dag ('NoneType' object has no attribute 'isoformat'; 148)
[2023-11-01T12:36:24.093+0700] {local_task_job_runner.py:228} INFO - Task exited with return code 1
[2023-11-01T12:36:24.118+0700] {taskinstance.py:2776} INFO - 0 downstream tasks scheduled from follow-on schedule check
